<!DOCTYPE html>
<html lang="en">

<head>
    <meta charset="UTF-8">
    <meta http-equiv="X-UA-Compatible" content="IE=edge">
    <meta name="viewport" content="width=device-width, initial-scale=1.0">
    <title>promise的几个关键问题6</title>
</head>

<body>
    <!-- 
        promise错误穿透：
            （1）当使用promise的then链式调用时，可以在最后用catch指定一个失败的回调
            （2）前面任何操作出了问题，都会传到最后失败的回调中处理
        备注：如果不存在then的链式调用，就不需要考虑then的错误穿透
     -->
    <script src="https://cdn.bootcdn.net/ajax/libs/jquery/3.6.0/jquery.js"></script>
    <script>
        function sendAjax(url, data,index) {
            return new Promise((resolve, reject) => {
                // 实例xhr
                const xhr = new XMLHttpRequest()
                // 绑定监听
                xhr.onreadystatechange = () => {
                    if (xhr.readyState === 4) {
                        if (xhr.status >= 200 && xhr.status < 300) {
                            resolve(xhr.response)
                        } else {
                            reject(`第${index}次请求出了点问题`)
                        }
                    }
                }
                // 整理参数
                let str = ''
                for (let key in data) {
                    str += `${key}=${data[key]}&`
                }
                str = str.slice(0, -1)
                xhr.open('GET', url + '?' + str)
                xhr.responseType = 'json'
                xhr.send()
            })
        }
        // 发送第一次请求
        sendAjax('https://api.apiopen.top/getJoke', { page: 1 },1)
        .then(
                value => {
                    console.log('第一次请求成功', value)
                    // 发送第二次请求
                    return sendAjax('https://api.apiopen.top/getJoke', { page: 1 },2)
                },
                /* reason => {
                    console.log(reason)
                    return new Promise(() => { })
                } */
            )
        .then(
                value => {
                    console.log('第二次请求成功', value)
                    // 发送第三次请求
                    return sendAjax('https://api.apiopen.top/getJoke', { page: 1 },3)
                },
                /* reason => {
                    console.log(reason)
                    return new Promise(() => { })
                } */
            )
        .then(
                value => {
                    console.log('第三次请求成功', value)
                },
                /* reason => {
                    console.log(reason)
                } */
            )
        .catch(
            reason=>{console.log(reason)}
        )


        // 另一个例子演示错误的穿透
        const p=new Promise((resolve,reject)=>{
            setTimeout(()=>{
                resolve('a')
            },1000)
        })
        p.then(
            value=>{console.log('成功了1',value);return 'b'},
            reason=>{throw reason}
        )
        .then(
            value=>{console.log('成功了2',value);return 'c'},
            reason=>{throw reason}
        )
        .catch(
            reason=>{console.log('失败了',reason)}
        )
    </script>
</body>

</html>